<?xml version="1.0" ?>
<sdf version="1.6">
  <model name="nix_tower">
    <pose frame=''>0 0 0 0 0 0</pose>
    
    <!-- Base -->
    <link name="base_link">
      <pose>0 0 0.0025 0 0 0</pose>
      <inertial>
        <mass>1</mass>
        <inertia>
          <ixx>0.003677</ixx>
          <iyy>0.003677</iyy>
          <izz>0.00735</izz>
          <ixy>0</ixy>
          <ixz>0</ixz>
          <iyz>0</iyz>
        </inertia>
      </inertial>
      <collision name="bl_collision">
        <geometry>
            <box>
              <size>.21 .21 .005</size>
            </box>
        </geometry>
      </collision>
      <visual name="bl_visual">
        <material>
                    
                      <ambient>0.2 0.2 0.2 1</ambient>
                      <diffuse>0.2 0.2 0.2 1</diffuse>
                      <specular>0.1 0.1 0.1 1</specular>
                    
                </material>
        <geometry>
            <box>
              <size>.21 .21 .005</size>
            </box>
        </geometry>
      </visual>
    </link>

    <!-- Tower -->
    <link name="stick_1">
      <pose>-0.1 -0.1 0.12 0 0 0</pose>
      <inertial>
        <mass>0.1</mass>
        <inertia>
          <ixx>0.000407</ixx>
          <iyy>0.000407</iyy>
          <izz>0.000006667</izz>
          <ixy>0</ixy>
          <ixz>0</ixz>
          <iyz>0</iyz>
        </inertia>
      </inertial>
      <collision name="stick_1_collision">
        <geometry>
            <box>
              <size>.02 .02 .22</size>
            </box>
        </geometry>
      </collision>
      <visual name="stick_1_visual">
        <material>
                    
                      <ambient>0.2 0.2 0.2 1</ambient>
                      <diffuse>0.2 0.2 0.2 1</diffuse>
                      <specular>0.1 0.1 0.1 1</specular>
                    
                </material>
        <geometry>
            <box>
              <size>.02 .02 .22</size>
            </box>
        </geometry>
      </visual>
    </link>
    <joint name="stick_1_joint" type="revolute">
      <child>stick_1</child>
      <parent>base_link</parent>
     
      <pose>-0.1 -0.1 0.12 0 0 0</pose>
       <axis>
        <limit>
          <lower>-0.001</lower>
          <upper>0.001</upper>
        </limit>
        <xyz>1 0 0</xyz>
        <dynamics>
          <spring_reference>0</spring_reference>
          <spring_stiffness>0</spring_stiffness>
          <damping>0.5</damping>
          <friction>4</friction>
        </dynamics>
      </axis>
    </joint>

    <link name="stick_2">
      <pose>0.1 -0.1 0.12 0 0 0</pose>
      <inertial>
        <mass>0.1</mass>
        <inertia>
          <ixx>0.000407</ixx>
          <iyy>0.000407</iyy>
          <izz>0.000006667</izz>
          <ixy>0</ixy>
          <ixz>0</ixz>
          <iyz>0</iyz>
        </inertia>
      </inertial>
      <collision name="stick_2_collision">
        <geometry>
            <box>
              <size>.02 .02 .22</size>
            </box>
        </geometry>
      </collision>
      <visual name="stick_2_visual">
        <material>
                    
                      <ambient>0.2 0.2 0.2 1</ambient>
                      <diffuse>0.2 0.2 0.2 1</diffuse>
                      <specular>0.1 0.1 0.1 1</specular>
                    
                </material>
        <geometry>
            <box>
              <size>.02 .02 .22</size>
            </box>
        </geometry>
      </visual>
    </link>
    <joint name="stick_2_joint" type="revolute">
      <child>stick_2</child>
      <parent>base_link</parent>
     
      <pose>0.1 -0.1 0.12 0 0 0</pose>
       <axis>
        <limit>
          <lower>-0.001</lower>
          <upper>0.001</upper>
        </limit>
        <xyz>1 0 0</xyz>
        <dynamics>
          <spring_reference>0</spring_reference>
          <spring_stiffness>0</spring_stiffness>
          <damping>0.5</damping>
          <friction>4</friction>
        </dynamics>
      </axis>
    </joint>

    <link name="stick_3">
      <pose>-0.1 0.1 0.12 0 0 0</pose>
      <inertial>
        <mass>0.1</mass>
        <inertia>
          <ixx>0.000407</ixx>
          <iyy>0.000407</iyy>
          <izz>0.000006667</izz>
          <ixy>0</ixy>
          <ixz>0</ixz>
          <iyz>0</iyz>
        </inertia>
      </inertial>
      <collision name="stick_3_collision">
        <geometry>
            <box>
              <size>.02 .02 .22</size>
            </box>
        </geometry>
      </collision>
      <visual name="stick_3_visual">
        <material>
                    
                      <ambient>0.2 0.2 0.2 1</ambient>
                      <diffuse>0.2 0.2 0.2 1</diffuse>
                      <specular>0.1 0.1 0.1 1</specular>
                    
                </material>
        <geometry>
            <box>
              <size>.02 .02 .22</size>
            </box>
        </geometry>
      </visual>
    </link>
    <joint name="stick_3_joint" type="revolute">
      <child>stick_3</child>
      <parent>base_link</parent>
     
      <pose>-0.1 0.1 0.12 0 0 0</pose>
       <axis>
        <limit>
          <lower>-0.001</lower>
          <upper>0.001</upper>
        </limit>
        <xyz>1 0 0</xyz>
        <dynamics>
          <spring_reference>0</spring_reference>
          <spring_stiffness>0</spring_stiffness>
          <damping>0.5</damping>
          <friction>4</friction>
        </dynamics>
      </axis>
    </joint>

    <link name="stick_4">
      <pose>0.1 0.1 0.12 0 0 0</pose>
      <inertial>
        <mass>0.1</mass>
        <inertia>
          <ixx>0.000407</ixx>
          <iyy>0.000407</iyy>
          <izz>0.000006667</izz>
          <ixy>0</ixy>
          <ixz>0</ixz>
          <iyz>0</iyz>
        </inertia>
      </inertial>
      <collision name="stick_4_collision">
        <geometry>
            <box>
              <size>.02 .02 .22</size>
            </box>
        </geometry>
      </collision>
      <visual name="stick_4_visual">
        <material>
                    
                      <ambient>0.2 0.2 0.2 1</ambient>
                      <diffuse>0.2 0.2 0.2 1</diffuse>
                      <specular>0.1 0.1 0.1 1</specular>
                    
                </material>
        <geometry>
            <box>
              <size>.02 .02 .22</size>
            </box>
        </geometry>
      </visual>
    </link>
    <joint name="stick_4_joint" type="revolute">
      <child>stick_4</child>
      <parent>base_link</parent>
     
      <pose>-0.1 -0.1 0.12 0 0 0</pose>
       <axis>
        <limit>
          <lower>-0.001</lower>
          <upper>0.001</upper>
        </limit>
        <xyz>1 0 0</xyz>
        <dynamics>
          <spring_reference>0</spring_reference>
          <spring_stiffness>0</spring_stiffness>
          <damping>0.5</damping>
          <friction>4</friction>
        </dynamics>
      </axis>
    </joint>

    <link name="plate">
      <pose>0 0 0.2325 0 0 0</pose>
      <inertial>
        <mass>0.1</mass>
        <inertia>
          <ixx>0.0024</ixx>
          <iyy>0.0024</iyy>
          <izz>0.0048</izz>
          <ixy>0</ixy>
          <ixz>0</ixz>
          <iyz>0</iyz>
        </inertia>
      </inertial>
      <collision name="plate_collision">
        <geometry>
            <box>
              <size>.21 .21 .005</size>
            </box>
        </geometry>
      </collision>
      <visual name="plate_visual">
        <material>
                    
                      <ambient>0.2 0.2 0.2 1</ambient>
                      <diffuse>0.2 0.2 0.2 1</diffuse>
                      <specular>0.1 0.1 0.1 1</specular>
                    
                    
                </material>
        <geometry>
            <box>
              <size>.21 .21 .005</size>
            </box>
        </geometry>
      </visual>
    </link>
    <joint name="plate_joint" type="fixed">
      <child>plate</child>
      <parent>base_link</parent>
      <pose>0 0 0 0 0 0</pose>
    </joint> 
  </model>
</sdf>
