<?xml version="1.0" ?>
<sdf version="1.6">

    <model name="raposaNG">
      <pose frame=''>0 2 0.071917 0 0 0</pose>
      <link name='base_link'>
          <pose frame=''>0 0 0 0 -0 0</pose>
          <inertial>
              <pose frame=''>-0.122 0 0.118 1.5707963267948966 -0 0</pose>
              <mass>13.14</mass>
              <inertia>
                  <ixx>0.10019</ixx>
                  <ixy>0</ixy>
                  <ixz>0</ixz>
                  <iyy>0.345043</iyy>
                  <iyz>0</iyz>
                  <izz>0.302044</izz>
              </inertia>
          </inertial>
          <collision name='base_link_collision'>
              <pose frame=''>-0.122 0 0.118 0 -0 0</pose>
              <geometry>
                  <box>
                      <size>0.50017 0.24093 0.139</size>
                  </box>
              </geometry>
          </collision>
          <visual name='base_link_visual'>
              <pose frame=''>-0.122 0 0.118 0 -0 0</pose>
              <geometry>
                  <box>
                      <size>0.50017 0.24093 0.139</size>
                  </box>
              </geometry>
              <material>
                <ambient>0.2 0.2 0.2 1</ambient>
                <diffuse>0.2 0.2 0.2 1</diffuse>
                <specular>0.1 0.1 0.1 1</specular>
              </material>
          </visual>
          <self_collide>0</self_collide>
          <gravity>1</gravity>
          <kinematic>0</kinematic>

          <sensor name="imu_sensor" type="imu">
            <always_on>1</always_on>
            <update_rate>1000</update_rate>
          </sensor>
      </link>

      <link name='left_track'>
          <pose frame=''>0 0.1985 0 0 -0 0</pose>
          <inertial>
              <mass>2.06</mass>
              <inertia>
                  <ixx>0.002731</ixx>
                  <ixy>0</ixy>
                  <ixz>0</ixz>
                  <iyy>0.032554</iyy>
                  <iyz>0</iyz>
                  <izz>0.031391</izz>
              </inertia>
          </inertial>
          <collision name='left_track_collision'>
              <pose frame=''>0 0 0.01855 1.5707963267948966  -0 1.5707963267948966</pose>
              <geometry>
                  <box>
                      <size>0.009728 0.018094 0.05</size>
                  </box>
              </geometry>
          </collision>
      </link>
      <joint name='left_track_j' type='fixed'>
          <child>left_track</child>
          <parent>base_link</parent>
      </joint>
      <link name='left_track_wheel1'>
          <pose frame=''>0.25 0.1985 0.01855 0 -0 0</pose>
          <inertial>
              <mass>0.5</mass>
              <inertia>
                  <ixx>0.001</ixx>
                  <ixy>0</ixy>
                  <ixz>0</ixz>
                  <iyy>0.001</iyy>
                  <iyz>0</iyz>
                  <izz>0.001</izz>
              </inertia>
          </inertial>
          <collision name='left_track_wheel1_collision'>
              <pose frame=''>0 0 0 1.5707963267948966 -0 0</pose>
              <geometry>
                  <cylinder>
                      <length>0.09728</length>
                      <radius>0.09047</radius>
                  </cylinder>
              </geometry>
              <surface>
                  <friction>
                      <ode>
                          <mu>0.5</mu>
                          <mu2>3.19858</mu2>
                          <fdir1>0 0 1</fdir1>
                          <slip1>0</slip1>
                          <slip2>0</slip2>
                      </ode>
                  </friction>
              </surface>
          </collision>
          <visual name='left_track_wheel1_visual'>
              <pose frame=''>0 0 0 1.5707963267948966 -0 0</pose>
              <geometry>
                  <cylinder>
                      <length>0.09728</length>
                      <radius>0.09047</radius>
                  </cylinder>
              </geometry>
          </visual>
      </link>
      <joint name='left_track_wheel1_j' type='revolute'>
          <child>left_track_wheel1</child>
          <parent>left_track</parent>
          <axis>
              <xyz>0 1 0</xyz>
              <limit>
                  <lower>-1e+16</lower>
                  <upper>1e+16</upper>
              </limit>
          </axis>
      </joint>
      <link name='left_track_wheel2'>
          <pose frame=''>0.1786 0.1985 0.01855 0 -0 0</pose>
          <inertial>
              <mass>0.5</mass>
              <inertia>
                  <ixx>0.001</ixx>
                  <ixy>0</ixy>
                  <ixz>0</ixz>
                  <iyy>0.001</iyy>
                  <iyz>0</iyz>
                  <izz>0.001</izz>
              </inertia>
          </inertial>
          <collision name='left_track_wheel2_collision'>
              <pose frame=''>0 0 0 1.5707963267948966 -0 0</pose>
              <geometry>
                  <cylinder>
                      <length>0.09728</length>
                      <radius>0.09047</radius>
                  </cylinder>
              </geometry>
              <surface>
                  <friction>
                      <ode>
                          <mu>0.5</mu>
                          <mu2>3.19858</mu2>
                          <fdir1>0 0 1</fdir1>
                          <slip1>0</slip1>
                          <slip2>0</slip2>
                      </ode>
                  </friction>
              </surface>
          </collision>
          <visual name='left_track_wheel2_visual'>
              <pose frame=''>0 0 0 1.5707963267948966 -0 0</pose>
              <geometry>
                  <cylinder>
                      <length>0.09728</length>
                      <radius>0.09047</radius>
                  </cylinder>
              </geometry>
          </visual>
      </link>
      <joint name='left_track_wheel2_j' type='revolute'>
          <child>left_track_wheel2</child>
          <parent>left_track</parent>
          <axis>
              <xyz>0 1 0</xyz>
              <limit>
                  <lower>-1e+16</lower>
                  <upper>1e+16</upper>
              </limit>
          </axis>
      </joint>
      <link name='left_track_wheel3'>
          <pose frame=''>0.1072 0.1985 0.01855 0 -0 0</pose>
          <inertial>
              <mass>0.5</mass>
              <inertia>
                  <ixx>0.001</ixx>
                  <ixy>0</ixy>
                  <ixz>0</ixz>
                  <iyy>0.001</iyy>
                  <iyz>0</iyz>
                  <izz>0.001</izz>
              </inertia>
          </inertial>
          <collision name='left_track_wheel3_collision'>
              <pose frame=''>0 0 0 1.5707963267948966 -0 0</pose>
              <geometry>
                  <cylinder>
                      <length>0.09728</length>
                      <radius>0.09047</radius>
                  </cylinder>
              </geometry>
              <surface>
                  <friction>
                      <ode>
                          <mu>0.5</mu>
                          <mu2>3.19858</mu2>
                          <fdir1>0 0 1</fdir1>
                          <slip1>0</slip1>
                          <slip2>0</slip2>
                      </ode>
                  </friction>
              </surface>
          </collision>
          <visual name='left_track_wheel3_visual'>
              <pose frame=''>0 0 0 1.5707963267948966 -0 0</pose>
              <geometry>
                  <cylinder>
                      <length>0.09728</length>
                      <radius>0.09047</radius>
                  </cylinder>
              </geometry>
          </visual>
      </link>
      <joint name='left_track_wheel3_j' type='revolute'>
          <child>left_track_wheel3</child>
          <parent>left_track</parent>
          <axis>
              <xyz>0 1 0</xyz>
              <limit>
                  <lower>-1e+16</lower>
                  <upper>1e+16</upper>
              </limit>
          </axis>
      </joint>
      <link name='left_track_wheel4'>
          <pose frame=''>-0.25 0.1985 0.01855 0 -0 0</pose>
          <inertial>
              <mass>0.5</mass>
              <inertia>
                  <ixx>0.001</ixx>
                  <ixy>0</ixy>
                  <ixz>0</ixz>
                  <iyy>0.001</iyy>
                  <iyz>0</iyz>
                  <izz>0.001</izz>
              </inertia>
          </inertial>
          <collision name='left_track_wheel4_collision'>
              <pose frame=''>0 0 0 1.5707963267948966 -0 0</pose>
              <geometry>
                  <cylinder>
                      <length>0.09728</length>
                      <radius>0.09047</radius>
                  </cylinder>
              </geometry>
              <surface>
                  <friction>
                      <ode>
                          <mu>0.5</mu>
                          <mu2>3.19858</mu2>
                          <fdir1>0 0 1</fdir1>
                          <slip1>0</slip1>
                          <slip2>0</slip2>
                      </ode>
                  </friction>
              </surface>
          </collision>
          <visual name='left_track_wheel4_visual'>
              <pose frame=''>0 0 0 1.5707963267948966 -0 0</pose>
              <geometry>
                  <cylinder>
                      <length>0.09728</length>
                      <radius>0.09047</radius>
                  </cylinder>
              </geometry>
          </visual>
      </link>
      <joint name='left_track_wheel4_j' type='revolute'>
          <child>left_track_wheel4</child>
          <parent>left_track</parent>
          <axis>
              <xyz>0 1 0</xyz>
              <limit>
                  <lower>-1e+16</lower>
                  <upper>1e+16</upper>
              </limit>
          </axis>
      </joint>
      <link name='left_track_wheel5'>
          <pose frame=''>-0.0358 0.1985 0.01855 0 -0 0</pose>
          <inertial>
              <mass>0.5</mass>
              <inertia>
                  <ixx>0.001</ixx>
                  <ixy>0</ixy>
                  <ixz>0</ixz>
                  <iyy>0.001</iyy>
                  <iyz>0</iyz>
                  <izz>0.001</izz>
              </inertia>
          </inertial>
          <collision name='left_track_wheel5_collision'>
              <pose frame=''>0 0 0 1.5707963267948966 -0 0</pose>
              <geometry>
                  <cylinder>
                      <length>0.09728</length>
                      <radius>0.09047</radius>
                  </cylinder>
              </geometry>
              <surface>
                  <friction>
                      <ode>
                          <mu>0.5</mu>
                          <mu2>3.19858</mu2>
                          <fdir1>0 0 1</fdir1>
                          <slip1>0</slip1>
                          <slip2>0</slip2>
                      </ode>
                  </friction>
              </surface>
          </collision>
          <visual name='left_track_wheel5_visual'>
              <pose frame=''>0 0 0 1.5707963267948966 -0 0</pose>
              <geometry>
                  <cylinder>
                      <length>0.09728</length>
                      <radius>0.09047</radius>
                  </cylinder>
              </geometry>
          </visual>
      </link>
      <joint name='left_track_wheel5_j' type='revolute'>
          <child>left_track_wheel5</child>
          <parent>left_track</parent>
          <axis>
              <xyz>0 1 0</xyz>
              <limit>
                  <lower>-1e+16</lower>
                  <upper>1e+16</upper>
              </limit>
          </axis>
      </joint>
      <link name='left_track_wheel6'>
          <pose frame=''>-0.1072 0.1985 0.01855 0 -0 0</pose>
          <inertial>
              <mass>0.5</mass>
              <inertia>
                  <ixx>0.001</ixx>
                  <ixy>0</ixy>
                  <ixz>0</ixz>
                  <iyy>0.001</iyy>
                  <iyz>0</iyz>
                  <izz>0.001</izz>
              </inertia>
          </inertial>
          <collision name='left_track_wheel6_collision'>
              <pose frame=''>0 0 0 1.5707963267948966 -0 0</pose>
              <geometry>
                  <cylinder>
                      <length>0.09728</length>
                      <radius>0.09047</radius>
                  </cylinder>
              </geometry>
              <surface>
                  <friction>
                      <ode>
                          <mu>0.5</mu>
                          <mu2>3.19858</mu2>
                          <fdir1>0 0 1</fdir1>
                          <slip1>0</slip1>
                          <slip2>0</slip2>
                      </ode>
                  </friction>
              </surface>
          </collision>
          <visual name='left_track_wheel6_visual'>
              <pose frame=''>0 0 0 1.5707963267948966 -0 0</pose>
              <geometry>
                  <cylinder>
                      <length>0.09728</length>
                      <radius>0.09047</radius>
                  </cylinder>
              </geometry>
          </visual>
          <gravity>1</gravity>
          <velocity_decay/>
          <kinematic>0</kinematic>
      </link>
      <joint name='left_track_wheel6_j' type='revolute'>
          <child>left_track_wheel6</child>
          <parent>left_track</parent>
          <axis>
              <xyz>0 1 0</xyz>
              <limit>
                  <lower>-1e+16</lower>
                  <upper>1e+16</upper>
              </limit>
          </axis>
      </joint>
      <link name='left_track_wheel7'>
          <pose frame=''>-0.1786 0.1985 0.01855 0 -0 0</pose>
          <inertial>
              <mass>0.5</mass>
              <inertia>
                  <ixx>0.001</ixx>
                  <ixy>0</ixy>
                  <ixz>0</ixz>
                  <iyy>0.001</iyy>
                  <iyz>0</iyz>
                  <izz>0.001</izz>
              </inertia>
          </inertial>
          <collision name='left_track_wheel7_collision'>
              <pose frame=''>0 0 0 1.5707963267948966 -0 0</pose>
              <geometry>
                  <cylinder>
                      <length>0.09728</length>
                      <radius>0.09047</radius>
                  </cylinder>
              </geometry>
              <surface>
                  <friction>
                      <ode>
                          <mu>0.5</mu>
                          <mu2>3.19858</mu2>
                          <fdir1>0 0 1</fdir1>
                          <slip1>0</slip1>
                          <slip2>0</slip2>
                      </ode>
                  </friction>
              </surface>
          </collision>
          <visual name='left_track_wheel7_visual'>
              <pose frame=''>0 0 0 1.5707963267948966 -0 0</pose>
              <geometry>
                  <cylinder>
                      <length>0.09728</length>
                      <radius>0.09047</radius>
                  </cylinder>
              </geometry>
          </visual>
      </link>
      <joint name='left_track_wheel7_j' type='revolute'>
          <child>left_track_wheel7</child>
          <parent>left_track</parent>
          <axis>
              <xyz>0 1 0</xyz>
              <limit>
                  <lower>-1e+16</lower>
                  <upper>1e+16</upper>
              </limit>
          </axis>
      </joint>
      <link name='left_track_wheel8'>
          <pose frame=''>0.0358 0.1985 0.01855 0 -0 0</pose>
          <inertial>
              <mass>0.5</mass>
              <inertia>
                  <ixx>0.001</ixx>
                  <ixy>0</ixy>
                  <ixz>0</ixz>
                  <iyy>0.001</iyy>
                  <iyz>0</iyz>
                  <izz>0.001</izz>
              </inertia>
          </inertial>
          <collision name='left_track_wheel8_collision'>
              <pose frame=''>0 0 0 1.5707963267948966 -0 0</pose>
              <geometry>
                  <cylinder>
                      <length>0.09728</length>
                      <radius>0.09047</radius>
                  </cylinder>
              </geometry>
              <surface>
                  <friction>
                      <ode>
                          <mu>0.5</mu>
                          <mu2>3.19858</mu2>
                          <fdir1>0 0 1</fdir1>
                          <slip1>0</slip1>
                          <slip2>0</slip2>
                      </ode>
                  </friction>
              </surface>
          </collision>
          <visual name='left_track_wheel8_visual'>
              <pose frame=''>0 0 0 1.5707963267948966 -0 0</pose>
              <geometry>
                  <cylinder>
                      <length>0.09728</length>
                      <radius>0.09047</radius>
                  </cylinder>
              </geometry>
          </visual>
      </link>
      <joint name='left_track_wheel8_j' type='revolute'>
          <child>left_track_wheel8</child>
          <parent>left_track</parent>
          <axis>
              <xyz>0 1 0</xyz>
              <limit>
                  <lower>-1e+16</lower>
                  <upper>1e+16</upper>
              </limit>
          </axis>
      </joint>

      <link name='right_track'>
          <pose frame=''>0 -0.1985 0 0 -0 0</pose>
          <inertial>
              <mass>2.06</mass>
              <inertia>
                  <ixx>0.002731</ixx>
                  <ixy>0</ixy>
                  <ixz>0</ixz>
                  <iyy>0.032554</iyy>
                  <iyz>0</iyz>
                  <izz>0.031391</izz>
              </inertia>
          </inertial>
          <collision name='right_track_collision'>
              <pose frame=''>0 0 0.01855 1.5707963267948966  -0 1.5707963267948966</pose>
              <geometry>
                  <box>
                      <size>0.009728 0.018094 0.05</size>
                  </box>
              </geometry>
          </collision>
      </link>
      <joint name='right_track_j' type='fixed'>
          <child>right_track</child>
          <parent>base_link</parent>
      </joint>

      <link name='right_track_wheel1'>
          <pose frame=''>0.25 -0.1985 0.01855 0 -0 0</pose>
          <inertial>
              <mass>0.5</mass>
              <inertia>
                  <ixx>0.001</ixx>
                  <ixy>0</ixy>
                  <ixz>0</ixz>
                  <iyy>0.001</iyy>
                  <iyz>0</iyz>
                  <izz>0.001</izz>
              </inertia>
          </inertial>
          <collision name='right_track_wheel1_collision'>
              <pose frame=''>0 0 0 1.5707963267948966 -0 0</pose>
              <geometry>
                  <cylinder>
                      <length>0.09728</length>
                      <radius>0.09047</radius>
                  </cylinder>
              </geometry>
              <surface>
                  <friction>
                      <ode>
                          <mu>0.5</mu>
                          <mu2>3.19858</mu2>
                          <fdir1>0 0 1</fdir1>
                          <slip1>0</slip1>
                          <slip2>0</slip2>
                      </ode>
                  </friction>
              </surface>
          </collision>
          <visual name='right_track_wheel1_visual'>
              <pose frame=''>0 0 0 1.5707963267948966 -0 0</pose>
              <geometry>
                  <cylinder>
                      <length>0.09728</length>
                      <radius>0.09047</radius>
                  </cylinder>
              </geometry>
          </visual>
      </link>
      <joint name='right_track_wheel1_j' type='revolute'>
          <child>right_track_wheel1</child>
          <parent>right_track</parent>
          <axis>
              <xyz>0 1 0</xyz>
              <limit>
                  <lower>-1e+16</lower>
                  <upper>1e+16</upper>
              </limit>
          </axis>
      </joint>
      <link name='right_track_wheel2'>
          <pose frame=''>0.1786 -0.1985 0.01855 0 -0 0</pose>
          <inertial>
              <mass>0.5</mass>
              <inertia>
                  <ixx>0.001</ixx>
                  <ixy>0</ixy>
                  <ixz>0</ixz>
                  <iyy>0.001</iyy>
                  <iyz>0</iyz>
                  <izz>0.001</izz>
              </inertia>
          </inertial>
          <collision name='right_track_wheel2_collision'>
              <pose frame=''>0 0 0 1.5707963267948966 -0 0</pose>
              <geometry>
                  <cylinder>
                      <length>0.09728</length>
                      <radius>0.09047</radius>
                  </cylinder>
              </geometry>
              <surface>
                  <friction>
                      <ode>
                          <mu>0.5</mu>
                          <mu2>3.19858</mu2>
                          <fdir1>0 0 1</fdir1>
                          <slip1>0</slip1>
                          <slip2>0</slip2>
                      </ode>
                  </friction>
              </surface>
          </collision>
          <visual name='right_track_wheel2_visual'>
              <pose frame=''>0 0 0 1.5707963267948966 -0 0</pose>
              <geometry>
                  <cylinder>
                      <length>0.09728</length>
                      <radius>0.09047</radius>
                  </cylinder>
              </geometry>
          </visual>
      </link>
      <joint name='right_track_wheel2_j' type='revolute'>
          <child>right_track_wheel2</child>
          <parent>right_track</parent>
          <axis>
              <xyz>0 1 0</xyz>
              <limit>
                  <lower>-1e+16</lower>
                  <upper>1e+16</upper>
              </limit>
          </axis>
      </joint>
      <link name='right_track_wheel3'>
          <pose frame=''>0.1072 -0.1985 0.01855 0 -0 0</pose>
          <inertial>
              <mass>0.5</mass>
              <inertia>
                  <ixx>0.001</ixx>
                  <ixy>0</ixy>
                  <ixz>0</ixz>
                  <iyy>0.001</iyy>
                  <iyz>0</iyz>
                  <izz>0.001</izz>
              </inertia>
          </inertial>
          <collision name='right_track_wheel3_collision'>
              <pose frame=''>0 0 0 1.5707963267948966 -0 0</pose>
              <geometry>
                  <cylinder>
                      <length>0.09728</length>
                      <radius>0.09047</radius>
                  </cylinder>
              </geometry>
              <surface>
                  <friction>
                      <ode>
                          <mu>0.5</mu>
                          <mu2>3.19858</mu2>
                          <fdir1>0 0 1</fdir1>
                          <slip1>0</slip1>
                          <slip2>0</slip2>
                      </ode>
                  </friction>
              </surface>
          </collision>
          <visual name='right_track_wheel3_visual'>
              <pose frame=''>0 0 0 1.5707963267948966 -0 0</pose>
              <geometry>
                  <cylinder>
                      <length>0.09728</length>
                      <radius>0.09047</radius>
                  </cylinder>
              </geometry>
          </visual>
      </link>
      <joint name='right_track_wheel3_j' type='revolute'>
          <child>right_track_wheel3</child>
          <parent>right_track</parent>
          <axis>
              <xyz>0 1 0</xyz>
              <limit>
                  <lower>-1e+16</lower>
                  <upper>1e+16</upper>
              </limit>
          </axis>
      </joint>
      <link name='right_track_wheel4'>
          <pose frame=''>-0.25 -0.1985 0.01855 0 -0 0</pose>
          <inertial>
              <mass>0.5</mass>
              <inertia>
                  <ixx>0.001</ixx>
                  <ixy>0</ixy>
                  <ixz>0</ixz>
                  <iyy>0.001</iyy>
                  <iyz>0</iyz>
                  <izz>0.001</izz>
              </inertia>
          </inertial>
          <collision name='right_track_wheel4_collision'>
              <pose frame=''>0 0 0 1.5707963267948966 -0 0</pose>
              <geometry>
                  <cylinder>
                      <length>0.09728</length>
                      <radius>0.09047</radius>
                  </cylinder>
              </geometry>
              <surface>
                  <friction>
                      <ode>
                          <mu>0.5</mu>
                          <mu2>3.19858</mu2>
                          <fdir1>0 0 1</fdir1>
                          <slip1>0</slip1>
                          <slip2>0</slip2>
                      </ode>
                  </friction>
              </surface>
          </collision>
          <visual name='right_track_wheel4_visual'>
              <pose frame=''>0 0 0 1.5707963267948966 -0 0</pose>
              <geometry>
                  <cylinder>
                      <length>0.09728</length>
                      <radius>0.09047</radius>
                  </cylinder>
              </geometry>
          </visual>
      </link>
      <joint name='right_track_wheel4_j' type='revolute'>
          <child>right_track_wheel4</child>
          <parent>right_track</parent>
          <axis>
              <xyz>0 1 0</xyz>
              <limit>
                  <lower>-1e+16</lower>
                  <upper>1e+16</upper>
              </limit>
          </axis>
      </joint>
      <link name='right_track_wheel5'>
          <pose frame=''>-0.0358 -0.1985 0.01855 0 -0 0</pose>
          <inertial>
              <mass>0.5</mass>
              <inertia>
                  <ixx>0.001</ixx>
                  <ixy>0</ixy>
                  <ixz>0</ixz>
                  <iyy>0.001</iyy>
                  <iyz>0</iyz>
                  <izz>0.001</izz>
              </inertia>
          </inertial>
          <collision name='right_track_wheel5_collision'>
              <pose frame=''>0 0 0 1.5707963267948966 -0 0</pose>
              <geometry>
                  <cylinder>
                      <length>0.09728</length>
                      <radius>0.09047</radius>
                  </cylinder>
              </geometry>
              <surface>
                  <friction>
                      <ode>
                          <mu>0.5</mu>
                          <mu2>3.19858</mu2>
                          <fdir1>0 0 1</fdir1>
                          <slip1>0</slip1>
                          <slip2>0</slip2>
                      </ode>
                  </friction>
              </surface>
          </collision>
          <visual name='right_track_wheel5_visual'>
              <pose frame=''>0 0 0 1.5707963267948966 -0 0</pose>
              <geometry>
                  <cylinder>
                      <length>0.09728</length>
                      <radius>0.09047</radius>
                  </cylinder>
              </geometry>
          </visual>
      </link>
      <joint name='right_track_wheel5_j' type='revolute'>
          <child>right_track_wheel5</child>
          <parent>right_track</parent>
          <axis>
              <xyz>0 1 0</xyz>
              <limit>
                  <lower>-1e+16</lower>
                  <upper>1e+16</upper>
              </limit>
          </axis>
      </joint>
      <link name='right_track_wheel6'>
          <pose frame=''>-0.1072 -0.1985 0.01855 0 -0 0</pose>
          <inertial>
              <mass>0.5</mass>
              <inertia>
                  <ixx>0.001</ixx>
                  <ixy>0</ixy>
                  <ixz>0</ixz>
                  <iyy>0.001</iyy>
                  <iyz>0</iyz>
                  <izz>0.001</izz>
              </inertia>
          </inertial>
          <collision name='right_track_wheel6_collision'>
              <pose frame=''>0 0 0 1.5707963267948966 -0 0</pose>
              <geometry>
                  <cylinder>
                      <length>0.09728</length>
                      <radius>0.09047</radius>
                  </cylinder>
              </geometry>
              <surface>
                  <friction>
                      <ode>
                          <mu>0.5</mu>
                          <mu2>3.19858</mu2>
                          <fdir1>0 0 1</fdir1>
                          <slip1>0</slip1>
                          <slip2>0</slip2>
                      </ode>
                  </friction>
              </surface>
          </collision>
          <visual name='right_track_wheel6_visual'>
              <pose frame=''>0 0 0 1.5707963267948966 -0 0</pose>
              <geometry>
                  <cylinder>
                      <length>0.09728</length>
                      <radius>0.09047</radius>
                  </cylinder>
              </geometry>
          </visual>
      </link>
      <joint name='right_track_wheel6_j' type='revolute'>
          <child>right_track_wheel6</child>
          <parent>right_track</parent>
          <axis>
              <xyz>0 1 0</xyz>
              <limit>
                  <lower>-1e+16</lower>
                  <upper>1e+16</upper>
              </limit>
          </axis>
      </joint>
      <link name='right_track_wheel7'>
          <pose frame=''>-0.1786 -0.1985 0.01855 0 -0 0</pose>
          <inertial>
              <mass>0.5</mass>
              <inertia>
                  <ixx>0.001</ixx>
                  <ixy>0</ixy>
                  <ixz>0</ixz>
                  <iyy>0.001</iyy>
                  <iyz>0</iyz>
                  <izz>0.001</izz>
              </inertia>
          </inertial>
          <collision name='right_track_wheel7_collision'>
              <pose frame=''>0 0 0 1.5707963267948966 -0 0</pose>
              <geometry>
                  <cylinder>
                      <length>0.09728</length>
                      <radius>0.09047</radius>
                  </cylinder>
              </geometry>
              <surface>
                  <friction>
                      <ode>
                          <mu>0.5</mu>
                          <mu2>3.19858</mu2>
                          <fdir1>0 0 1</fdir1>
                          <slip1>0</slip1>
                          <slip2>0</slip2>
                      </ode>
                  </friction>
              </surface>
          </collision>
          <visual name='right_track_wheel7_visual'>
              <pose frame=''>0 0 0 1.5707963267948966 -0 0</pose>
              <geometry>
                  <cylinder>
                      <length>0.09728</length>
                      <radius>0.09047</radius>
                  </cylinder>
              </geometry>
          </visual>
      </link>
      <joint name='right_track_wheel7_j' type='revolute'>
          <child>right_track_wheel7</child>
          <parent>right_track</parent>
          <axis>
              <xyz>0 1 0</xyz>
              <limit>
                  <lower>-1e+16</lower>
                  <upper>1e+16</upper>
              </limit>
          </axis>
      </joint>
      <link name='right_track_wheel8'>
          <pose frame=''>0.0358 -0.1985 0.01855 0 -0 0</pose>
          <inertial>
              <mass>0.5</mass>
              <inertia>
                  <ixx>0.001</ixx>
                  <ixy>0</ixy>
                  <ixz>0</ixz>
                  <iyy>0.001</iyy>
                  <iyz>0</iyz>
                  <izz>0.001</izz>
              </inertia>
          </inertial>
          <collision name='right_track_wheel8_collision'>
              <pose frame=''>0 0 0 1.5707963267948966 -0 0</pose>
              <geometry>
                  <cylinder>
                      <length>0.09728</length>
                      <radius>0.09047</radius>
                  </cylinder>
              </geometry>
              <surface>
                  <friction>
                      <ode>
                          <mu>0.5</mu>
                          <mu2>3.19858</mu2>
                          <fdir1>0 0 1</fdir1>
                          <slip1>0</slip1>
                          <slip2>0</slip2>
                      </ode>
                  </friction>
              </surface>
          </collision>
          <visual name='right_track_wheel8_visual'>
              <pose frame=''>0 0 0 1.5707963267948966 -0 0</pose>
              <geometry>
                  <cylinder>
                      <length>0.09728</length>
                      <radius>0.09047</radius>
                  </cylinder>
              </geometry>
          </visual>
      </link>
      <joint name='right_track_wheel8_j' type='revolute'>
          <child>right_track_wheel8</child>
          <parent>right_track</parent>
          <axis>
              <xyz>0 1 0</xyz>
              <limit>
                  <lower>-1e+16</lower>
                  <upper>1e+16</upper>
              </limit>
          </axis>
      </joint>

      <!-- Track drive -->
      <plugin filename="ignition-gazebo-diff-drive-system"
              name="ignition::gazebo::systems::DiffDrive">
        <left_joint>left_track_wheel1_j</left_joint>
        <right_joint>right_track_wheel1_j</right_joint>
        <left_joint>left_track_wheel2_j</left_joint>
        <right_joint>right_track_wheel2_j</right_joint>
        <left_joint>left_track_wheel3_j</left_joint>
        <right_joint>right_track_wheel3_j</right_joint>
        <left_joint>left_track_wheel4_j</left_joint>
        <right_joint>right_track_wheel4_j</right_joint>
        <left_joint>left_track_wheel5_j</left_joint>
        <right_joint>right_track_wheel5_j</right_joint>
        <left_joint>left_track_wheel6_j</left_joint>
        <right_joint>right_track_wheel6_j</right_joint>
        <left_joint>left_track_wheel7_j</left_joint>
        <right_joint>right_track_wheel7_j</right_joint>
        <left_joint>left_track_wheel8_j</left_joint>
        <right_joint>right_track_wheel8_j</right_joint>
        <wheel_separation>0.493</wheel_separation>
        <wheel_radius>0.09047</wheel_radius>
      </plugin>

    </model>
<!-- Original model -->
    <!-- <model name="raposaNG">
        <pose frame=''>0 0 0 0 0 0</pose>

        <link name='base_link'>
            <pose frame=''>0 0 0 0 0 0</pose>
            <inertial>
                <pose frame=''>-0.062 0 0.03 1.5708 -0 0</pose>

                <mass>25.14</mass>
                <inertia>
                    <ixx>0.1611</ixx>
                    <ixy>0</ixy>
                    <ixz>0</ixz>
                    <iyy>0.64</iyy>
                    <iyz>0</iyz>
                    <izz>0.56</izz>
                </inertia>
            </inertial>
            <collision name='base_link_collision'>
                <pose frame=''>-0.062 0 0.03 0 -0 0</pose>
                <geometry>
                    <box>
                        <size>0.50017 0.24093 0.139</size>
                    </box>
                </geometry>
            </collision>
            <visual name='base_link_visual'>
                <pose frame=''>-0.062 0 0.03 0 -0 0</pose>
                <geometry>
                    <box>
                        <size>0.46017 0.28093 0.139</size>

                    </box>
                </geometry>
                <material>
                    <ambient> 0 0 0 1 </ambient>
                    <diffuse> 0 0 0 1 </diffuse>
                    <specular> 0 0 0 1 </specular>
                </material>
            </visual>
            <self_collide>0</self_collide>
            <gravity>1</gravity>
            <kinematic>0</kinematic>


            
            <sensor name="imu_sensor" type="imu">
                <always_on>true</always_on>
                <update_rate>100</update_rate>
                <visualize>true</visualize>
                <topic>imu</topic>
                <plugin filename="libgazebo_ros_imu_sensor.so" name="imu_plugin">
                <topicName>imu</topicName>
                <bodyName>imu_link</bodyName>
                <updateRateHZ>100.0</updateRateHZ>
                <gaussianNoise>0</gaussianNoise>
                <xyzOffset>0 0 0</xyzOffset>
                <rpyOffset>0 0 0</rpyOffset>
                <frameName>imu_link</frameName>
                </plugin>
                <pose>0 0 0 0 0 0</pose>
            </sensor> 
        </link>

        <link name='left_track'>
            <pose frame=''>0 0.1985 0 0 -0 0</pose>
            <inertial>
                <pose frame=''>0 0 0.0141 0 -0 0</pose>
                <mass>6.06</mass>
                <inertia>
                    <ixx>0.031391</ixx>
                    <ixy>0</ixy>
                    <ixz>0</ixz>
                    <iyy>0.182731</iyy>
                    <iyz>1.5e-05</iyz>
                    <izz>0.162554</izz>
                </inertia>
            </inertial>
            <collision name='left_track_collision'>
                <pose frame=''>0 0 0.01855 1.5708 -0 1.5708</pose>
                <geometry>
                    <box>
                        <size>0.09728 0.18094 0.5</size>
                    </box>
                </geometry>
                <surface>
                    <friction>
                        <ode>
                            <mu>0.7</mu>
                            <mu2>150</mu2>
                            <fdir1>0 1 0</fdir1>
                        </ode>
                    </friction>
                </surface>
            </collision>
            <collision name='left_track_collision_1'>
                <pose frame=''>0.25 0 0.01855 1.5708 -0 0</pose>
                <geometry>
                    <cylinder>
                        <length>0.09728</length>
                        <radius>0.09047</radius>
                    </cylinder>
                </geometry>
                <surface>
                    <friction>
                        <ode>
                            <mu>0.7</mu>
                            <mu2>150</mu2>
                            <fdir1>0 1 0</fdir1>
                        </ode>
                    </friction>
                </surface>
            </collision>
            <collision name='left_track_collision_2'>
                <pose frame=''>-0.25 0 0.01855 1.5708 -0 0</pose>
                <geometry>
                    <cylinder>
                        <length>0.09728</length>
                        <radius>0.09047</radius>
                    </cylinder>
                </geometry>
                <surface>
                    <friction>
                        <ode>
                            <mu>0.7</mu>
                            <mu2>150</mu2>
                            <fdir1>0 1 0</fdir1>
                        </ode>
                    </friction>
                </surface>
            </collision>
            <visual name='left_track_visual'>
                <material>
                    <ambient> 0 0 0 1 </ambient>
                    <diffuse> 0 0 0 1 </diffuse>
                    <specular> 0 0 0 1 </specular>
                </material>
                <pose frame=''>0 0 0.01855 1.5708 -0 1.5708</pose>
                <geometry>
                    <box>
                        <size>0.09728 0.18094 0.5</size>
                    </box>
                </geometry>
            </visual>
            <visual name='left_track_visual_1'>
                <material>
                    <ambient> 0 0 0 1 </ambient>
                    <diffuse> 0 0 0 1 </diffuse>
                    <specular> 0 0 0 1 </specular>
                </material>
                <pose frame=''>0.25 0 0.01855 1.5708 -0 0</pose>
                <geometry>
                    <cylinder>
                        <length>0.09728</length>
                        <radius>0.09047</radius>
                    </cylinder>
                </geometry>
            </visual>
            <visual name='left_track_visual_2'>
                <material>
                    <ambient> 0 0 0 1 </ambient>
                    <diffuse> 0 0 0 1 </diffuse>
                    <specular> 0 0 0 1 </specular>
                </material>
                <pose frame=''>-0.25 0 0.01855 1.5708 -0 0</pose>
                <geometry>
                    <cylinder>
                        <length>0.09728</length>
                        <radius>0.09047</radius>
                    </cylinder>
                </geometry>
            </visual>
            <gravity>1</gravity>
            <kinematic>0</kinematic>
        </link>
        <joint name='left_track_j' type='fixed'>
            <child>left_track</child>
            <parent>base_link</parent>
        </joint>

        <link name='right_track'>
            <pose frame=''>0 -0.1985 0 0 -0 0</pose>
            <inertial>
                <pose frame=''>0 0 0.0141 0 -0 0</pose>
                <mass>6.06</mass>
                <inertia>
                    <ixx>0.031391</ixx>
                    <ixy>0</ixy>
                    <ixz>0</ixz>
                    <iyy>0.182731</iyy>
                    <iyz>1.5e-05</iyz>
                    <izz>0.162554</izz>
                </inertia>
            </inertial>
            <collision name='right_track_collision'>
                <pose frame=''>0 0 0.01855 1.5708 -0 1.5708</pose>
                <geometry>
                    <box>
                        <size>0.09728 0.18094 0.5</size>
                    </box>
                </geometry>
                <surface>
                    <friction>
                        <ode>
                            <mu>0.7</mu>
                            <mu2>150</mu2>
                            <fdir1>0 1 0</fdir1>
                        </ode>
                    </friction>
                </surface>
            </collision>
            <collision name='right_track_collision_1'>
                <pose frame=''>0.25 0 0.01855 1.5708 -0 0</pose>
                <geometry>
                    <cylinder>
                        <length>0.09728</length>
                        <radius>0.09047</radius>
                    </cylinder>
                </geometry>
                <surface>
                    <friction>
                        <ode>
                            <mu>0.7</mu>
                            <mu2>150</mu2>
                            <fdir1>0 1 0</fdir1>
                        </ode>
                    </friction>
                </surface>
            </collision>
            <collision name='right_track_collision_2'>
                <pose frame=''>-0.25 0 0.01855 1.5708 -0 0</pose>
                <geometry>
                    <cylinder>
                        <length>0.09728</length>
                        <radius>0.09047</radius>
                    </cylinder>
                </geometry>
                <surface>
                    <friction>
                        <ode>
                            <mu>0.7</mu>
                            <mu2>150</mu2>
                            <fdir1>0 1 0</fdir1>
                        </ode>
                    </friction>
                </surface>
            </collision>
            <visual name='right_track_visual'>
                <material>
                    <ambient> 0 0 0 1 </ambient>
                    <diffuse> 0 0 0 1 </diffuse>
                    <specular> 0 0 0 1 </specular>
                </material>
                <pose frame=''>0 0 0.01855 1.5708 -0 1.5708</pose>
                <geometry>
                    <box>
                        <size>0.09728 0.18094 0.5</size>
                    </box>
                </geometry>
            </visual>
            <visual name='right_track_visual_1'>
                <material>
                    <ambient> 0 0 0 1 </ambient>
                    <diffuse> 0 0 0 1 </diffuse>
                    <specular> 0 0 0 1 </specular>
                </material>
                <pose frame=''>0.25 0 0.01855 1.5708 -0 0</pose>
                <geometry>
                    <cylinder>
                        <length>0.09728</length>
                        <radius>0.09047</radius>
                    </cylinder>
                </geometry>
            </visual>
            <visual name='right_track_visual_2'>
                <material>
                    <ambient> 0 0 0 1 </ambient>
                    <diffuse> 0 0 0 1 </diffuse>
                    <specular> 0 0 0 1 </specular>
                </material>
                <pose frame=''>-0.25 0 0.01855 1.5708 -0 0</pose>
                <geometry>
                    <cylinder>
                        <length>0.09728</length>
                        <radius>0.09047</radius>
                    </cylinder>
                </geometry>
            </visual>
            <gravity>1</gravity>
            <kinematic>0</kinematic>
        </link>
        <joint name='right_track_j' type='fixed'>
            <child>right_track</child>
            <parent>base_link</parent>
        </joint>

        
        
        <link name='front_left_flipper'>
            <pose frame=''>0.25 0.122 0.0195 0 -0.5 0</pose>
            <inertial>
                <pose frame=''>0.08 0 0 0 -0 0</pose>
                <mass>0.75</mass>
                <inertia>
                    <ixx>0.0017491</ixx>
                    <ixy>2.8512e-07</ixy>
                    <ixz>0.0018277</ixz>
                    <iyy>0.012277</iyy>
                    <iyz>-3.6288e-07</iyz>
                    <izz>0.010941</izz>
                </inertia>
            </inertial>
            <collision name='front_left_flipper_collision_large_wheel_collision'>
                <pose frame=''>0 -0 0 1.5708 -0 0</pose>
                <geometry>
                    <cylinder>
                        <length>0.04981</length>
                        <radius>0.089</radius>
                    </cylinder>
                </geometry>
                <surface>
                    <friction>
                        <ode>
                            <mu>0.7</mu>
                            <mu2>150</mu2>
                            <fdir1>0 1 0</fdir1>
                        </ode>
                    </friction>
                    <contact>
                        <ode/>
                    </contact>
                </surface>
                <max_contacts>50</max_contacts>
            </collision>
            <collision name='front_left_flipper_collision_small_wheel_collision_1'>
                <pose frame=''>0.25 -0 0 1.5708 -0 0</pose>

                <geometry>
                    <cylinder>
                        <length>0.04981</length>
                        <radius>0.04</radius>
                    </cylinder>
                </geometry>
                <surface>
                    <friction>
                        <ode>
                            <mu>0.7</mu>
                            <mu2>150</mu2>
                            <fdir1>0 1 0</fdir1>
                        </ode>
                    </friction>
                    <contact>
                        <ode/>
                    </contact>
                </surface>
                <max_contacts>50</max_contacts>
            </collision>
            <collision name='front_left_flipper_collision_top_bar_collision_2'>
                <pose frame=''>0.165 -0 0.0325 0 0.184162 0</pose>
                <geometry>
                    <box>
                        <size>0.33 0.04981 0.055</size>
                    </box>
                </geometry>
                <surface>
                    <friction>
                        <ode>
                            <mu>0.7</mu>
                            <mu2>150</mu2>
                            <fdir1>0 1 0</fdir1>
                        </ode>
                    </friction>
                    <contact>
                        <ode/>
                    </contact>
                </surface>
                <max_contacts>50</max_contacts>
            </collision>
            <collision name='front_left_flipper_collision_bottom_bar_collision_3'>
                <pose frame=''>0.165 -0 -0.0325 0 -0.184162 0</pose>
                <geometry>
                    <box>
                        <size>0.33 0.04981 0.055</size>
                    </box>
                </geometry>
                <surface>
                    <friction>
                        <ode>
                            <mu>0.7</mu>
                            <mu2>150</mu2>
                            <fdir1>0 1 0</fdir1>
                        </ode>
                    </friction>
                    <contact>
                        <ode/>
                    </contact>
                </surface>
                <max_contacts>50</max_contacts>
            </collision>
            <visual name='front_left_flipper_visual_large_wheel_visual'>
                <material>
                    <ambient> 0 0 0 1 </ambient>
                    <diffuse> 0 0 0 1 </diffuse>
                    <specular> 0 0 0 1 </specular>
                </material>
                <pose frame=''>0 -0 0 1.5708 -0 0</pose>
                <geometry>
                    <cylinder>
                        <length>0.04981</length>
                        <radius>0.089</radius>
                    </cylinder>
                </geometry>
            </visual>
            <visual name='front_left_flipper_visual_small_wheel_visual_1'>
                <material>
                    <ambient> 0 0 0 1 </ambient>
                    <diffuse> 0 0 0 1 </diffuse>
                    <specular> 0 0 0 1 </specular>
                </material>
                <pose frame=''>0.28 -0 0 1.5708 -0 0</pose>

                <geometry>
                    <cylinder>
                        <length>0.04981</length>
                        <radius>0.037</radius>
                    </cylinder>
                </geometry>
            </visual>
            <visual name='front_left_flipper_visual_top_bar_visual_2'>
                <material>
                    <ambient> 0 0 0 1 </ambient>
                    <diffuse> 0 0 0 1 </diffuse>
                    <specular> 0 0 0 1 </specular>
                </material>
                <pose frame=''>0.14 -0 0.0325 0 0.184162 0</pose>
                <geometry>
                    <box>
                        <size>0.28 0.04981 0.055</size>
                    </box>
                </geometry>
            </visual>
            <visual name='front_left_flipper_visual_bottom_bar_visual_3'>
                <material>
                    <ambient> 0 0 0 1 </ambient>
                    <diffuse> 0 0 0 1 </diffuse>
                    <specular> 0 0 0 1 </specular>
                </material>
                <pose frame=''>0.14 -0 -0.0325 0 -0.184162 0</pose>
                <geometry>
                    <box>
                        
                        <size>0.28 0.04981 0.055</size>
                    </box>
                </geometry>
            </visual>
            <visual name='front_left_flipper_visual_middle_bar_visual_4'>
                <material>
                    <ambient> 0 0 0 1 </ambient>
                    <diffuse> 0 0 0 1 </diffuse>
                    <specular> 0 0 0 1 </specular>
                </material>
                <pose frame=''>0.14 -0 0.004 0 -0.02 0</pose>
                <geometry>
                    <box>
                        <size>0.28 0.04981 0.07</size>
                    </box>
                </geometry>
            </visual>
            <gravity>1</gravity>
            <velocity_decay/>
            <self_collide>1</self_collide>
            <kinematic>0</kinematic>
        </link>
        <joint name='front_left_flipper_j' type='revolute'>
            <child>front_left_flipper</child>
            <parent>left_track</parent>
            <axis>
                <xyz>0 1 0</xyz>
                <limit>
                    <lower>0</lower>
                    <upper>0</upper>
                </limit>
                <dynamics>
                    <spring_reference>0</spring_reference>
                    <spring_stiffness>0</spring_stiffness>
                </dynamics>
                <use_parent_model_frame>1</use_parent_model_frame>
            </axis>
            <physics>
                <ode>
                    <implicit_spring_damper>1</implicit_spring_damper>
                    <cfm_damping>1</cfm_damping>
                    <limit>
                        <cfm>0</cfm>
                        <erp>0.2</erp>
                    </limit>
                </ode>
            </physics>
        </joint>
        <link name='front_right_flipper'>
            <pose frame=''>0.25 -0.122 0.0195 3.14159 0.5 3.14159</pose>
            <inertial>
                <pose frame=''>-0.08 0 0 0 -0 0</pose>
                <mass>0.75</mass>
                <inertia>
                    <ixx>0.0017491</ixx>
                    <ixy>2.8512e-07</ixy>
                    <ixz>0.0018277</ixz>
                    <iyy>0.012277</iyy>
                    <iyz>-3.6288e-07</iyz>
                    <izz>0.010941</izz>
                </inertia>
            </inertial>
            <collision name='front_right_flipper_collision_large_wheel_collision'>
                <pose frame=''>0 0 0 1.5708 -0 0</pose>
                <geometry>
                    <cylinder>
                        <length>0.04981</length>
                        <radius>0.089</radius>
                    </cylinder>
                </geometry>
                <surface>
                    <friction>
                        <ode>
                            <mu>0.7</mu>
                            <mu2>150</mu2>
                            <fdir1>0 1 0</fdir1>
                        </ode>
                    </friction>
                    <contact>
                        <ode/>
                    </contact>
                </surface>
                <max_contacts>50</max_contacts>
            </collision>
            <collision name='front_right_flipper_collision_small_wheel_collision_1'>
                <pose frame=''>-0.28 0 0 1.5708 -0 0</pose>
                <geometry>
                    <cylinder>
                        <length>0.04981</length>
                        <radius>0.037</radius>
                    </cylinder>
                </geometry>
                <surface>
                    <friction>
                        <ode>
                            <mu>0.7</mu>
                            <mu2>150</mu2>
                            <fdir1>0 1 0</fdir1>
                        </ode>
                    </friction>
                    <contact>
                        <ode/>
                    </contact>
                </surface>
                <max_contacts>50</max_contacts>
            </collision>
            <collision name='front_right_flipper_collision_top_bar_collision_2'>
                <pose frame=''>-0.14 0 0.0325 0 0.184162 -3.14159</pose>

                <geometry>
                    <box>
                        <size>0.28 0.04981 0.055</size>
                    </box>
                </geometry>
                <surface>
                    <friction>
                        <ode>
                            <mu>0.7</mu>
                            <mu2>150</mu2>
                            <fdir1>0 1 0</fdir1>
                        </ode>
                    </friction>
                    <contact>
                        <ode/>
                    </contact>
                </surface>
                <max_contacts>50</max_contacts>
            </collision>
            <collision name='front_right_flipper_collision_bottom_bar_collision_3'>
                <pose frame=''>-0.14 0 -0.0325 0 -0.184162 -3.14159</pose>
                
                <geometry>
                    <box>
                        <size>0.28 0.04981 0.055</size>
                    </box>
                </geometry>
                <surface>
                    <friction>
                        <ode>
                            <mu>0.7</mu>
                            <mu2>150</mu2>
                            <fdir1>0 1 0</fdir1>
                        </ode>
                    </friction>
                    <contact>
                        <ode/>
                    </contact>
                </surface>
                <max_contacts>50</max_contacts>
            </collision>
            <visual name='front_right_flipper_visual_large_wheel_visual'>
                <material>
                    <ambient> 0 0 0 1 </ambient>
                    <diffuse> 0 0 0 1 </diffuse>
                    <specular> 0 0 0 1 </specular>
                </material>
                <pose frame=''>0 0 0 1.5708 -0 0</pose>
                <geometry>
                    <cylinder>
                        <length>0.04981</length>
                        <radius>0.089</radius>
                    </cylinder>
                </geometry>
            </visual>
            <visual name='front_right_flipper_visual_small_wheel_visual_1'>
                <material>
                    <ambient> 0 0 0 1 </ambient>
                    <diffuse> 0 0 0 1 </diffuse>
                    <specular> 0 0 0 1 </specular>
                </material>
                
                <pose frame=''>-0.28 0 0 1.5708 -0 0</pose>
                <geometry>
                    <cylinder>
                        <length>0.04981</length>
                        <radius>0.037</radius>                        
                    </cylinder>
                </geometry>
            </visual>
            <visual name='front_right_flipper_visual_top_bar_visual_2'>
                <material>
                    <ambient> 0 0 0 1 </ambient>
                    <diffuse> 0 0 0 1 </diffuse>
                    <specular> 0 0 0 1 </specular>
                </material>                
                <pose frame=''>-0.14 0 0.0325 0 0.184162 -3.14159</pose>

                <geometry>
                    <box>                        
                        <size>0.28 0.04981 0.055</size>

                    </box>
                </geometry>
            </visual>
            <visual name='front_right_flipper_visual_bottom_bar_visual_3'>
                <material>
                    <ambient> 0 0 0 1 </ambient>
                    <diffuse> 0 0 0 1 </diffuse>
                    <specular> 0 0 0 1 </specular>
                </material>
                <pose frame=''>-0.14 0 -0.0325 0 -0.184162 -3.14159</pose>
                <geometry>
                    <box>
                        <size>0.28 0.04981 0.055</size>
                    </box>
                </geometry>
            </visual>
            <visual name='front_right_flipper_visual_middle_bar_visual_4'>
                <material>
                    <ambient> 0 0 0 1 </ambient>
                    <diffuse> 0 0 0 1 </diffuse>
                    <specular> 0 0 0 1 </specular>
                </material>
                <pose frame=''>-0.14 0 0.004 -0 -0.02 -3.14159</pose>
                <geometry>
                    <box>
                        <size>0.28 0.04981 0.07</size>
                    </box>
                </geometry>
            </visual>
            <gravity>1</gravity>
            <velocity_decay/>
            <self_collide>1</self_collide>
            <kinematic>0</kinematic>
        </link>
        <joint name='front_right_flipper_j' type='revolute'>
            <child>front_right_flipper</child>
            <parent>right_track</parent>
            <axis>
                <xyz>0 1 0</xyz>
                <limit>
                    <lower>0</lower>
                    <upper>0</upper>
                </limit>
                <dynamics>
                    <spring_reference>0</spring_reference>
                    <spring_stiffness>0</spring_stiffness>
                </dynamics>
                <use_parent_model_frame>1</use_parent_model_frame>
            </axis>
            <physics>
                <ode>
                    <implicit_spring_damper>1</implicit_spring_damper>
                    <cfm_damping>1</cfm_damping>
                    <limit>
                        <cfm>0</cfm>
                        <erp>0.2</erp>
                    </limit>
                </ode>
            </physics>
        </joint>

        

    </model> -->

 

</sdf>
